Workbook

Sheet summary
D5: CBSE norms | H5: National Curricular Framework norms
D6: Grades IX and X | E6: Grades VI, VII and VIII | F6: Grades III, IV & V | G6: Grades IX and X | H6: Grades VI, VII and VIII | I6: Grades III, IV & V
C7: English | D7: 160 | E7: 140 | F7: 140 | G7: 84 | H7: 97 | I7: 270
C8: Second language | D8: 140 | E8: 120 | F8: 100 | G8: 84 | H8: 105 | I8: 285
C9: Third language | G9: 84 | H9: 112
C10: Math | D10: 210 | E10: 180 | F10: 160 | G10: 162 | H10: 172 | I10: 277
C11: Science/EVS | D11: 210 | E11: 180 | F11: 140 | G11: 162 | H11: 240 | I11: 300
C12: Social Sciences | D12: 245 | E12: 210 | F12: 0 | G12: 150 | H12: 240
C13: Interdisciplinary Area | D13: 32 | E13: 70 | F13: 70 | G13: 150
C14: Scholastic subjects Total | D14: =SUM(D7:D13) -> 997 | E14: =SUM(E7:E13) -> 900 | F14: =SUM(F7:F13) -> 610 | G14: =SUM(G7:G13) -> 876 | H14: =SUM(H7:H13) -> 966 | I14: =SUM(I7:I13) -> 1132
C15: Art Education | D15: 32 | E15: 140 | F15: 260 | G15: 138 | H15: 150 | I15: 150
C16: Physical Education | D16: 0 | E16: 70 | F16: 64 | G16: 108 | H16: 150 | I16: 150
C17: Vocational Education / Life Skills /Computer Lab | D17: 64 | E17: 70 | F17: 64 | G17: 132 | H17: 165
C18: SOL/Culture/CTP | D18: 64 | E18: 225 | F18: 128
C19: Co-scholastic subjects Total | D19: =SUM(D15:D18) -> 160 | E19: =SUM(E15:E18) -> 505 | F19: =SUM(F15:F18) -> 516 | G19: =SUM(G15:G18) -> 378 | H19: =SUM(H15:H18) -> 465 | I19: =SUM(I15:I18) -> 300
C21: TOTAL | D21: =D14+D19 -> 1157 | E21: =E14+E19 -> 1405 | F21: =F14+F19 -> 1126 | G21: =G14+G19 -> 1254 | H21: =H14+H19 -> 1431 | I21: =I14+I19 -> 1432
C23: Scholastic subjects | D23: =D14/D21 -> 0.86171132 | E23: =E14/E21 -> 0.6405694 | F23: =F14/F21 -> 0.54174067 | G23: =G14/G21 -> 0.69856459 | H23: =H14/H21 -> 0.67505241 | I23: =I14/I21 -> 0.79050279
C24: Co-scholastic subjects | D24: =D19/D21 -> 0.13828868 | E24: =E19/E21 -> 0.3594306 | F24: =F19/F21 -> 0.45825933 | G24: =G19/G21 -> 0.30143541 | H24: =H19/H21 -> 0.32494759 | I24: =I19/I21 -> 0.20949721

Sheet NCF summary
D3: Preparatory school (3rd to 5th)
C4: Percentage | E4: No. of classes
C5: NCF guidance | D5: RBS | E5: NCF guidance | F5: 5th | G5: 4th | H5: 3rd
B6: R1 (English) + Library | C6: =E6/$E$14 -> 0.18848168 | D6: =AVERAGE(F6:H6)/AVERAGE($F$14:$H$14) -> 0.19148936 | E6: 270 | F6: ='RBS class wise'!BA9+'RBS class wise'!BA12 -> 228 | G6: ='RBS class wise'!BJ9+'RBS class wise'!BJ12 -> 228 | H6: ='RBS class wise'!BS9+'RBS class wise'!BS12 -> 228
B7: R2 (Hindi) | C7: =E7/$E$14 -> 0.19895288 | D7: =AVERAGE(F7:H7)/AVERAGE($F$14:$H$14) -> 0.095744681 | E7: 285 | F7: ='RBS class wise'!BA8 -> 114 | G7: ='RBS class wise'!BJ8 -> 114 | H7: ='RBS class wise'!BS8 -> 114
B8: R3 (Sanskrit) | D8: =AVERAGE(F8:H8)/AVERAGE($F$14:$H$14) -> 0.031914894 | E8: 0 | F8: ='RBS class wise'!BA15 -> 38
B9: Mathematics | C9: =E9/$E$14 -> 0.19371728 | D9: =AVERAGE(F9:H9)/AVERAGE($F$14:$H$14) -> 0.13829787 | E9: 277.5 | F9: ='RBS class wise'!BA11 -> 190 | G9: ='RBS class wise'!BJ11 -> 152 | H9: ='RBS class wise'!BS11 -> 152
B10: TWAU / EVS | C10: =E10/$E$14 -> 0.20942408 | D10: =AVERAGE(F10:H10)/AVERAGE($F$14:$H$14) -> 0.10638298 | E10: 300 | F10: ='RBS class wise'!BA10 -> 152 | G10: ='RBS class wise'!BJ10 -> 114 | H10: ='RBS class wise'!BS10 -> 114
B11: Art Education (incl. RGA) | C11: =E11/$E$14 -> 0.10471204 | D11: =AVERAGE(F11:H11)/AVERAGE($F$14:$H$14) -> 0.36170213 | E11: 150 | F11: ='RBS class wise'!BA13+'RBS class wise'!BA14+'RBS class wise'!BA17+'RBS class wise'!BA18+'RBS class wise'!BA19+'RBS class wise'!BA20+'RBS class wise'!BA21 -> 456 | G11: ='RBS class wise'!BJ13+'RBS class wise'!BJ14+'RBS class wise'!BJ15+'RBS class wise'!BJ17+'RBS class wise'!BJ18+'RBS class wise'!BJ19+'RBS class wise'!BJ20 -> 418 | H11: ='RBS class wise'!BS13+'RBS class wise'!BS14+'RBS class wise'!BS15+'RBS class wise'!BS17+'RBS class wise'!BS18+'RBS class wise'!BS19+'RBS class wise'!BS20 -> 418
B12: Physical Education / Games | C12: =E12/$E$14 -> 0.10471204 | D12: =AVERAGE(F12:H12)/AVERAGE($F$14:$H$14) -> 0.031914894 | E12: 150 | F12: ='RBS class wise'!BA16 -> 38 | G12: ='RBS class wise'!BJ16 -> 38 | H12: ='RBS class wise'!BS16 -> 38
B13: SOL/Culture/CTP | C13: =E13/$E$14 -> 0 | D13: =AVERAGE(F13:H13)/AVERAGE($F$14:$H$14) -> 0.063829787 | F13: ='RBS class wise'!BA6+'RBS class wise'!BA7 -> 76 | G13: ='RBS class wise'!BJ6+'RBS class wise'!BJ7 -> 76 | H13: ='RBS class wise'!BS6+'RBS class wise'!BS7 -> 76
C14: =SUM(C6:C13) -> 1 | D14: 1 | E14: =SUM(E6:E13) -> 1432.5 | F14: =SUM(F6:F13) -> 1292 | G14: =SUM(G6:G13) -> 1140 | H14: =SUM(H6:H13) -> 1140
D15: Middle school (6th to 8th)
C16: Percentage | E16: No. of classes
C17: NCF guidance | D17: RBS | E17: NCF guidance | F17: 8th | G17: 7th | H17: 6th
B18: R1 (English) + Library | C18: =E18/$E$28 -> 0.068062827 | D18: =AVERAGE(F18:H18)/AVERAGE($F$28:$H$28) -> 0.15315315 | E18: 97.5 | F18: ='RBS class wise'!Z10+'RBS class wise'!Z14 -> 222 | G18: ='RBS class wise'!AI10+'RBS class wise'!AI14 -> 222 | H18: ='RBS class wise'!AR10+'RBS class wise'!AR14 -> 185
B19: R2 (Hindi) | C19: =E19/$E$28 -> 0.073298429 | D19: =AVERAGE(F19:H19)/AVERAGE($F$28:$H$28) -> 0.081081081 | E19: 105 | F19: ='RBS class wise'!Z9 -> 111 | G19: ='RBS class wise'!AI9 -> 111 | H19: ='RBS class wise'!AR9 -> 111
B20: R3 (Sanskrit) | C20: =E20/$E$28 -> 0.078534031 | D20: =AVERAGE(F20:H20)/AVERAGE($F$28:$H$28) -> 0.054054054 | E20: 112.5 | F20: ='RBS class wise'!Z13 -> 74 | G20: ='RBS class wise'!AI13 -> 74 | H20: ='RBS class wise'!AR13 -> 74
B21: Mathematics | C21: =E21/$E$28 -> 0.12041885 | D21: =AVERAGE(F21:H21)/AVERAGE($F$28:$H$28) -> 0.15315315 | E21: 172.5 | F21: ='RBS class wise'!Z12 -> 222 | G21: ='RBS class wise'!AI12 -> 222 | H21: ='RBS class wise'!AR12 -> 185
B22: Science | C22: =E22/$E$28 -> 0.16753927 | D22: =AVERAGE(F22:H22)/AVERAGE($F$28:$H$28) -> 0.13513514 | E22: 240 | F22: ='RBS class wise'!Z11 -> 185 | G22: ='RBS class wise'!AI11 -> 185 | H22: ='RBS class wise'!AR11 -> 185
B23: Social Science | C23: =E23/$E$28 -> 0.16753927 | D23: =AVERAGE(F23:H23)/AVERAGE($F$28:$H$28) -> 0.10810811 | E23: 240 | F23: ='RBS class wise'!Z17 -> 148 | G23: ='RBS class wise'!AI17 -> 148 | H23: ='RBS class wise'!AR17 -> 148
B24: Art Education (incl. RGA) | C24: =E24/$E$28 -> 0.10471204 | D24: =AVERAGE(F24:H24)/AVERAGE($F$28:$H$28) -> 0.15315315 | E24: 150 | F24: ='RBS class wise'!Z16+'RBS class wise'!Z15+'RBS class wise'!Z20 -> 185 | G24: ='RBS class wise'!AI16+'RBS class wise'!AI15+'RBS class wise'!AI20 -> 185 | H24: ='RBS class wise'!AR15+'RBS class wise'!AR16+'RBS class wise'!AR19+'RBS class wise'!AR21 -> 259
B25: Physical Education / Games | C25: =E25/$E$28 -> 0.10471204 | D25: =AVERAGE(F25:H25)/AVERAGE($F$28:$H$28) -> 0.027027027 | E25: 150 | F25: ='RBS class wise'!Z18 -> 37 | G25: ='RBS class wise'!AI18 -> 37 | H25: ='RBS class wise'!AR18 -> 37
B26: Vocational Education / Life Skills | C26: =E26/$E$28 -> 0.11518325 | D26: =AVERAGE(F26:H26)/AVERAGE($F$28:$H$28) -> 0.054054054 | E26: 165 | F26: ='RBS class wise'!Z19 -> 74 | G26: ='RBS class wise'!AI19 -> 74 | H26: ='RBS class wise'!AR20 -> 74
B27: SOL/Culture/CTP | C27: =E27/$E$28 -> 0 | D27: =AVERAGE(F27:H27)/AVERAGE($F$28:$H$28) -> 0.081081081 | F27: ='RBS class wise'!Z6+'RBS class wise'!Z7+'RBS class wise'!Z8 -> 111 | G27: ='RBS class wise'!AI6+'RBS class wise'!AI7+'RBS class wise'!AI8 -> 111 | H27: ='RBS class wise'!AR6+'RBS class wise'!AR7+'RBS class wise'!AR8 -> 111
C28: =E28/$E$28 -> 1 | D28: =AVERAGE(F28:H28)/AVERAGE($F$28:$H$28) -> 1 | E28: =SUM(E18:E27) -> 1432.5 | F28: =SUM(F18:F27) -> 1369 | G28: =SUM(G18:G27) -> 1369 | H28: =SUM(H18:H27) -> 1369
D30: Secondary stage (9th & 10th)
C31: Percentage | E31: No. of classes
C32: NCF guidance | D32: RBS | E32: NCF guidance | F32: 10th | G32: 9th
B33: R1 (English) + Library | C33: =E33/$E$43 -> 0.066985646 | D33: =AVERAGE(F33:F33)/AVERAGE($F$43:$F$43) -> 0.17484389 | E33: 84 | F33: ='RBS class wise'!H9+'RBS class wise'!H18 -> 196 | G33: ='RBS class wise'!Q9+'RBS class wise'!Q18 -> 203
B34: R2 & R3 (Hindi/Sanskrit) | C34: =E34/$E$43 -> 0.13397129 | D34: =AVERAGE(F34:F34)/AVERAGE($F$43:$F$43) -> 0.099910794 | E34: =84+84 -> 168 | F34: ='RBS class wise'!H8 -> 112 | G34: ='RBS class wise'!Q8 -> 116
B35: Mathematics | C35: =E35/$E$43 -> 0.1291866 | D35: =AVERAGE(F35:F35)/AVERAGE($F$43:$F$43) -> 0.14986619 | E35: 162 | F35: ='RBS class wise'!H10 -> 168 | G35: ='RBS class wise'!Q10 -> 174
B36: Science | C36: =E36/$E$43 -> 0.1291866 | D36: =AVERAGE(F36:F36)/AVERAGE($F$43:$F$43) -> 0.22479929 | E36: 162 | F36: ='RBS class wise'!H11+'RBS class wise'!H12+'RBS class wise'!H13 -> 252 | G36: ='RBS class wise'!Q11+'RBS class wise'!Q12+'RBS class wise'!Q13 -> 261
B37: Social Science/interdisciplinary* | C37: =E37/$E$43 -> 0.23923445 | D37: =AVERAGE(F37:F37)/AVERAGE($F$43:$F$43) -> 0.22479929 | E37: 300 | F37: ='RBS class wise'!H14+'RBS class wise'!H15+'RBS class wise'!H16 -> 252 | G37: ='RBS class wise'!Q14+'RBS class wise'!Q15+'RBS class wise'!Q16 -> 261
B38: Art Education (incl. RGA) | C38: =E38/$E$43 -> 0.11004785 | D38: =AVERAGE(F38:F38)/AVERAGE($F$43:$F$43) -> 0.049955397 | E38: 138 | F38: ='RBS class wise'!H17 -> 56 | G38: ='RBS class wise'!Q17 -> 58
B39: Physical Education / Games | C39: =E39/$E$43 -> 0.086124402 | D39: =AVERAGE(F39:F39)/AVERAGE($F$43:$F$43) -> 0 | E39: 108 | F39: ='RBS class wise'!AI45 -> 0 | G39: ='RBS class wise'!Z45 -> 0
B40: Vocational Education / Life Skills | C40: =E40/$E$43 -> 0.10526316 | D40: =AVERAGE(F40:F40)/AVERAGE($F$43:$F$43) -> 0 | E40: 132 | F40: ='RBS class wise'!AI46 -> 0 | G40: ='RBS class wise'!Z46 -> 0
B41: SOL/Culture/CTP | C41: =E41/$E$43 -> 0 | D41: =AVERAGE(F41:F41)/AVERAGE($F$43:$F$43) -> 0.049955397 | F41: ='RBS class wise'!H6+'RBS class wise'!H7 -> 56 | G41: ='RBS class wise'!Q6+'RBS class wise'!Q7 -> 58
B42: Computer lab | C42: =E42/$E$43 -> 0 | D42: =AVERAGE(F42:F42)/AVERAGE($F$43:$F$43) -> 0.025869759 | F42: 29 | G42: 28
C43: =SUM(C33:C42) -> 1 | D43: =SUM(D33:D42) -> 1 | E43: =SUM(E33:E41) -> 1254 | F43: =SUM(F33:F42) -> 1121 | G43: =SUM(G33:G42) -> 1159
...

Sheet CBSE summary
G4: RBS period allocation versus CBSE benchmark - 2024-25
D6: Secondary Stage | G6: Middle School | K6: Preparatory stage
D7: CBSE norms | E7: Class 10 | F7: Class 9 | G7: CBSE norms | H7: Class 8 | I7: Class 7 | J7: Class 6 | K7: CBSE norms | L7: Class 5 | M7: Class 4 | N7: Class 3
C8: English | D8: 160 | E8: ='NCF summary'!F33-'RBS class wise'!H18 -> 168 | F8: ='NCF summary'!G33-'RBS class wise'!Q18 -> 174 | G8: 160 | H8: ='NCF summary'!F18-'RBS class wise'!Z14 -> 185 | I8: ='NCF summary'!G18-'RBS class wise'!AI14 -> 185 | J8: ='NCF summary'!H18-'RBS class wise'!AR14 -> 148 | K8: 140 | L8: ='NCF summary'!F6-'RBS class wise'!BA12 -> 152 | M8: ='NCF summary'!G6-'RBS class wise'!BJ12 -> 152 | N8: ='NCF summary'!H6-'RBS class wise'!BS12 -> 152
C9: Second language | D9: 140 | E9: ='NCF summary'!F34 -> 112 | F9: ='NCF summary'!G34 -> 116 | G9: 140 | H9: ='NCF summary'!F19 -> 111 | I9: ='NCF summary'!G19 -> 111 | J9: ='NCF summary'!H19 -> 111 | K9: 100 | L9: ='NCF summary'!F7 -> 114 | M9: ='NCF summary'!G7 -> 114 | N9: ='NCF summary'!H7 -> 114
C10: Third language | H10: ='NCF summary'!F20 -> 74 | I10: ='NCF summary'!G20 -> 74 | J10: ='NCF summary'!H20 -> 74 | L10: ='NCF summary'!F8 -> 38 | M10: ='NCF summary'!G8 -> 0 | N10: ='NCF summary'!H8 -> 0
C11: Math | D11: 210 | E11: ='NCF summary'!F35 -> 168 | F11: ='NCF summary'!G35 -> 174 | G11: 210 | H11: ='NCF summary'!F21 -> 222 | I11: ='NCF summary'!G21 -> 222 | J11: ='NCF summary'!H21 -> 185 | K11: 160 | L11: ='NCF summary'!F9 -> 190 | M11: ='NCF summary'!G9 -> 152 | N11: ='NCF summary'!H9 -> 152
C12: Science/EVS | D12: 210 | E12: ='NCF summary'!F36 -> 252 | F12: ='NCF summary'!G36 -> 261 | G12: 210 | H12: ='NCF summary'!F22 -> 185 | I12: ='NCF summary'!G22 -> 185 | J12: ='NCF summary'!H22 -> 185 | K12: 140 | L12: ='NCF summary'!F10 -> 152 | M12: ='NCF summary'!G10 -> 114 | N12: ='NCF summary'!H10 -> 114
C13: Social Sciences | D13: 245 | E13: ='NCF summary'!F37 -> 252 | F13: ='NCF summary'!G37 -> 261 | G13: 210 | H13: ='NCF summary'!F23 -> 148 | I13: ='NCF summary'!G23 -> 148 | J13: ='NCF summary'!H23 -> 148 | K13: 0
C14: LIB | D14: 32 | E14: ='RBS class wise'!H18 -> 28 | F14: ='RBS class wise'!Q18 -> 29 | G14: 70 | H14: ='RBS class wise'!Z14 -> 37 | I14: ='RBS class wise'!AI14 -> 37 | J14: ='RBS class wise'!AR14 -> 37 | K14: 70 | L14: ='RBS class wise'!BA12 -> 76 | M14: ='RBS class wise'!BJ12 -> 76 | N14: ='RBS class wise'!BS12 -> 76
C15: Scholastic subjects Total | D15: =SUM(D8:D14) -> 997 | E15: =SUM(E8:E14) -> 980 | F15: =SUM(F8:F14) -> 1015 | G15: =SUM(G8:G14) -> 1000 | H15: =SUM(H8:H14) -> 962 | I15: =SUM(I8:I14) -> 962 | J15: =SUM(J8:J14) -> 888 | K15: =SUM(K8:K14) -> 610 | ... N15: =SUM(N8:N14) -> 608
C16: Art Education | D16: 32 | E16: ='NCF summary'!F38 -> 56 | F16: ='NCF summary'!G38 -> 58 | G16: 140 | H16: ='NCF summary'!F24 -> 185 | I16: ='NCF summary'!G24 -> 185 | J16: ='NCF summary'!H24 -> 259 | K16: 260 | L16: ='NCF summary'!F11 -> 456 | M16: ='NCF summary'!G11 -> 418 | N16: ='NCF summary'!H11 -> 418
C17: Physical Education | D17: 0 | E17: ='NCF summary'!F39 -> 0 | F17: ='NCF summary'!G39 -> 0 | G17: 70 | H17: ='NCF summary'!F25 -> 37 | I17: ='NCF summary'!G25 -> 37 | J17: ='NCF summary'!H25 -> 37 | K17: 64 | L17: ='NCF summary'!F12 -> 38 | M17: ='NCF summary'!G12 -> 38 | N17: ='NCF summary'!H12 -> 38
C18: Vocational Education / Life Skills /Computer Lab | D18: 64 | E18: ='NCF summary'!F42 -> 29 | F18: ='NCF summary'!G42 -> 28 | G18: 70 | H18: ='NCF summary'!F26 -> 74 | I18: ='NCF summary'!G26 -> 74 | J18: ='NCF summary'!H26 -> 74 | K18: 64
C19: SOL/Culture/CTP | D19: 64 | E19: ='NCF summary'!F41 -> 56 | F19: ='NCF summary'!G41 -> 58 | G19: 225 | H19: ='NCF summary'!F27 -> 111 | I19: ='NCF summary'!G27 -> 111 | J19: ='NCF summary'!H27 -> 111 | K19: 128 | L19: ='NCF summary'!F13 -> 76 | M19: ='NCF summary'!G13 -> 76 | N19: ='NCF summary'!H13 -> 76
C20: Co-scholastic subjects Total | D20: =SUM(D16:D19) -> 160 | E20: =SUM(E16:E19) -> 141 | F20: =SUM(F16:F19) -> 144 | G20: =SUM(G16:G19) -> 505 | H20: =SUM(H16:H19) -> 407 | I20: =SUM(I16:I19) -> 407 | J20: =SUM(J16:J19) -> 481 | K20: =SUM(K16:K19) -> 516 | ... N20: =SUM(N16:N19) -> 532
C22: TOTAL | D22: =D15+D20 -> 1157 | E22: =E15+E20 -> 1121 | F22: =F15+F20 -> 1159 | G22: =G15+G20 -> 1505 | H22: =H15+H20 -> 1369 | I22: =I15+I20 -> 1369 | J22: =J15+J20 -> 1369 | K22: =K15+K20 -> 1126 | ... N22: =N15+N20 -> 1140
C24: Scholastic subjects | D24: =D15/D22 -> 0.86171132 | E24: =E15/E22 -> 0.87421945 | F24: =F15/F22 -> 0.87575496 | G24: =G15/G22 -> 0.66445183 | H24: =H15/H22 -> 0.7027027 | I24: =I15/I22 -> 0.7027027 | J24: =J15/J22 -> 0.64864865 | K24: =K15/K22 -> 0.54174067 | ... N24: =N15/N22 -> 0.53333333
C25: Co-scholastic subjects | D25: =D20/D22 -> 0.13828868 | E25: =E20/E22 -> 0.12578055 | F25: =F20/F22 -> 0.12424504 | G25: =G20/G22 -> 0.33554817 | H25: =H20/H22 -> 0.2972973 | I25: =I20/I22 -> 0.2972973 | J25: =J20/J22 -> 0.35135135 | K25: =K20/K22 -> 0.45825933 | ... N25: =N20/N22 -> 0.46666667

Sheet RBS class wise
A2: Class | B2: Subjects | C2: No. of classes (weekly) | D2: Term-1 | F2: Term-2 | H2: Total | J2: Class | K2: Subjects | L2: No. of classes (weekly) | M2: Term-1 | O2: Term-2 | Q2: Total | S2: Class | T2: Subjects | U2: No. of classes (weekly) | V2: Term-1 | X2: Term-2 | Z2: Total | AB2: Class | AC2: Subjects | AD2: No. of classes (weekly) | AE2: Term-1 | AG2: Term-2 | AI2: Total | AK2: Class | AL2: Subjects | AM2: No. of classes (weekly) | AN2: Term-1 | AP2: Term-2 | AR2: Total | AT2: Class | AU2: Subjects | AV2: No. of classes (weekly) | AW2: Term-1 | AY2: Term-2 | BA2: Total | BC2: Class | BD2: Subjects | BE2: No. of classes (weekly) | BF2: Term-1 | BH2: Term-2 | BJ2: Total | BL2: Class | BM2: Subjects | BN2: No. of classes (weekly) | BO2: Term-1 | BQ2: Term-2 | BS2: Total
D4: 18th Mar - 26th Apr | E4: 1st Jul- 26th Oct | F4: 15th Nov- 26th Dec | G4: 20th Jan – 1st Feb | M4: 1st Apr- 26th Apr | N4: 1st Jul- 26th Oct | O4: 15th Nov- 26th Dec | P4: 20th Jan – 5th Feb | V4: 1st Apr- 26th Apr | W4: 1st Jul- 26th Oct | X4: 15th Nov- 26th Dec | Y4: 20th Jan – 29th Mar | AE4: 1st Apr- 26th Apr | AF4: 1st Jul- 26th Oct | AG4: 15th Nov- 26th Dec | AH4: 20th Jan – 29th Mar | AN4: 1st Apr- 26th Apr | AO4: 1st Jul- 26th Oct | AP4: 15th Nov- 26th Dec | AQ4: 20th Jan – 29th Mar | AW4: 1st Apr- 26th Apr | AX4: 1st Jul- 26th Oct | AY4: 15th Nov- 26th Dec | AZ4: 20th Jan – 29th Mar | BF4: 1st Apr- 26th Apr | BG4: 1st Jul- 26th Oct | BH4: 15th Nov- 26th Dec | BI4: 20th Jan – 29th Mar | BO4: 1st Apr- 26th Apr | BP4: 1st Jul- 26th Oct | BQ4: 15th Nov- 26th Dec | BR4: 20th Jan – 29th Mar
D5: (6 weeks) | E5: (16 weeks) | F5: (4 weeks) approx. | G5: (2 weeks) | M5: (4 weeks) | N5: (16 weeks) | O5: (6 weeks) | P5: (3 weeks) Approx. | V5: (4 weeks) | W5: (16 weeks) | X5: (6 weeks) | Y5: (11 weeks) | AE5: (4 weeks) | AF5: (16 weeks) | AG5: (6 weeks) | AH5: (11 weeks) | AN5: (4 weeks) | AO5: (16 weeks) | AP5: (6 weeks) | AQ5: (11 weeks) | AW5: (4 weeks) | AX5: (17 weeks) | AY5: (6 weeks) | AZ5: (11 weeks) | BF5: (4 weeks) | BG5: (17 weeks) | BH5: (6 weeks) | BI5: (11 weeks) | BO5: (4 weeks) | BP5: (17 weeks) | BQ5: (6 weeks) | BR5: (11 weeks)
B6: CTP | C6: 1 | D6: 22 | F6: 6 | H6: 28 | K6: CTP | L6: 1 | M6: 20 | O6: 9 | Q6: 29 | T6: CTP | U6: 1 | V6: 20 | X6: 17 | Z6: 37 | AC6: CTP | AD6: 1 | AE6: 20 | AG6: 17 | AI6: 37 | AL6: CTP | AM6: 1 | AN6: 20 | AP6: 17 | AR6: 37 | AU6: CTP | AV6: 1 | AW6: 21 | AY6: 17 | BA6: 38 | BD6: CTP | BE6: 1 | BF6: 21 | BH6: 17 | BJ6: 38 | BM6: CTP | BN6: 1 | BO6: 21 | BQ6: 17 | BS6: 38
B7: Culture/SOL | C7: 1 | D7: 22 | F7: 6 | H7: 28 | K7: Culture/SOL | L7: 1 | M7: 20 | O7: 9 | Q7: 29 | T7: Culture | U7: 1 | V7: 20 | X7: 17 | Z7: 37 | AC7: Culture | AD7: 1 | AE7: 20 | AG7: 17 | AI7: 37 | AL7: Culture | AM7: 1 | AN7: 20 | AP7: 17 | AR7: 37 | AU7: Sol | AV7: 1 | AW7: 21 | AY7: 17 | BA7: 38 | BD7: Sol | BE7: 1 | BF7: 21 | BH7: 17 | BJ7: 38 | BM7: Sol | BN7: 1 | BO7: 21 | BQ7: 17 | BS7: 38
B8: Hindi/Sanskrit | C8: 4 | D8: 88 | F8: 24 | H8: 112 | K8: Hindi/Sanskrit | L8: 4 | M8: 80 | O8: 36 | Q8: 116 | T8: SOL | U8: 1 | V8: 20 | X8: 17 | Z8: 37 | AC8: SOL | AD8: 1 | AE8: 20 | AG8: 17 | AI8: 37 | AL8: SOL | AM8: 1 | AN8: 20 | AP8: 17 | AR8: 37 | AU8: Hindi | AV8: 3 | AW8: 63 | AY8: 51 | BA8: 114 | BD8: Hindi | BE8: 3 | BF8: 63 | BH8: 51 | BJ8: 114 | BM8: Hindi | BN8: 3 | BO8: 63 | BQ8: 51 | BS8: 114
B9: English | C9: 6 | D9: 132 | F9: 36 | H9: 168 | K9: English | L9: 6 | M9: 120 | O9: 54 | Q9: 174 | T9: Hindi | U9: 3 | V9: 60 | X9: 51 | Z9: 111 | AC9: Hindi | AD9: 3 | AE9: 60 | AG9: 51 | AI9: 111 | AL9: Hindi | AM9: 3 | AN9: 60 | AP9: 51 | AR9: 111 | AU9: English | AV9: 4 | AW9: 84 | AY9: 68 | BA9: 152 | BD9: English | BE9: 4 | BF9: 84 | BH9: 68 | BJ9: 152 | BM9: English | BN9: 4 | BO9: 84 | BQ9: 68 | BS9: 152
A10: 10th | B10: Math | C10: 6 | D10: 132 | F10: 36 | H10: 168 | J10: 9th | K10: Math | L10: 6 | M10: 120 | O10: 54 | Q10: 174 | S10: 8th | T10: English | U10: 5 | V10: 100 | X10: 85 | Z10: 185 | AB10: 7th | AC10: English | AD10: 5 | AE10: 100 | AG10: 85 | AI10: 185 | AK10: 6th | AL10: English | AM10: 4 | AN10: 80 | AP10: 68 | AR10: 148 | AT10: 5th | AU10: EVS | AV10: 4 | AW10: 84 | AY10: 68 | BA10: 152 | BC10: 4th | BD10: EVS | BE10: 3 | BF10: 63 | BH10: 51 | BJ10: 114 | BL10: 3rd | BM10: EVS | BN10: 3 | BO10: 63 | BQ10: 51 | BS10: 114
B11: Biology | C11: 3 | D11: 66 | F11: 18 | H11: 84 | K11: Biology | L11: 3 | M11: 60 | O11: 27 | Q11: 87 | T11: Science | U11: 5 | V11: 100 | X11: 85 | Z11: 185 | AC11: Science | AD11: 5 | AE11: 100 | AG11: 85 | AI11: 185 | AL11: Science | AM11: 5 | AN11: 100 | AP11: 85 | AR11: 185 | AU11: Math | AV11: 5 | AW11: 105 | AY11: 85 | BA11: 190 | BD11: Math | BE11: 4 | BF11: 84 | BH11: 68 | BJ11: 152 | BM11: Math | BN11: 4 | BO11: 84 | BQ11: 68 | BS11: 152
B12: Chemistry | C12: 3 | D12: 66 | F12: 18 | H12: 84 | K12: Chemistry | L12: 3 | M12: 60 | O12: 27 | Q12: 87 | T12: Math | U12: 6 | V12: 120 | X12: 102 | Z12: 222 | AC12: Math | AD12: 6 | AE12: 120 | AG12: 102 | AI12: 222 | AL12: Math | AM12: 5 | AN12: 100 | AP12: 85 | AR12: 185 | AU12: Library | AV12: 2 | AW12: 42 | AY12: 34 | BA12: 76 | BD12: Library | BE12: 2 | BF12: 42 | BH12: 34 | BJ12: 76 | BM12: Library | BN12: 2 | BO12: 42 | BQ12: 34 | BS12: 76
B13: Physics | C13: 3 | D13: 66 | F13: 18 | H13: 84 | K13: Physics | L13: 3 | M13: 60 | O13: 27 | Q13: 87 | T13: Sanskrit | U13: 2 | V13: 40 | X13: 34 | Z13: 74 | AC13: Sanskrit | AD13: 2 | AE13: 40 | AG13: 34 | AI13: 74 | AL13: Sanskrit | AM13: 2 | AN13: 40 | AP13: 34 | AR13: 74 | AU13: Pottery | AV13: 2 | AW13: 42 | AY13: 34 | BA13: 76 | BD13: Pottery | BE13: 2 | BF13: 42 | BH13: 34 | BJ13: 76 | BM13: Pottery | BN13: 2 | BO13: 42 | BQ13: 34 | BS13: 76
B14: History/Pol.Sci | C14: 4 | D14: 88 | F14: 24 | H14: 112 | K14: History/Pol.Sci | L14: 4 | M14: 80 | O14: 36 | Q14: 116 | T14: Library | U14: 1 | V14: 20 | X14: 17 | Z14: 37 | AC14: Library | AD14: 1 | AE14: 20 | AG14: 17 | AI14: 37 | AL14: Library | AM14: 1 | AN14: 20 | AP14: 17 | AR14: 37 | AU14: Dance | AV14: 2 | AW14: 42 | AY14: 34 | BA14: 76 | BD14: Dance | BE14: 2 | BF14: 42 | BH14: 34 | BJ14: 76 | BM14: Dance | BN14: 2 | BO14: 42 | BQ14: 34 | BS14: 76
B15: Geography | C15: 3 | D15: 66 | F15: 18 | H15: 84 | K15: Geography | L15: 3 | M15: 60 | O15: 27 | Q15: 87 | T15: Visual Arts | U15: 2 | V15: 40 | X15: 34 | Z15: 74 | AC15: Visual Arts | AD15: 2 | AE15: 40 | AG15: 34 | AI15: 74 | AL15: Pottery/Craft | AM15: 2 | AN15: 40 | AP15: 34 | AR15: 74 | AU15: Sanskrit | AV15: 1 | AW15: 21 | AY15: 17 | BA15: 38 | BD15: Nature Walk | BE15: 1 | BF15: 21 | BH15: 17 | BJ15: 38 | BM15: Nature Walk | BN15: 1 | BO15: 21 | BQ15: 17 | BS15: 38
B16: Economics | C16: 2 | D16: 44 | F16: 12 | H16: 56 | K16: Economics | L16: 2 | M16: 40 | O16: 18 | Q16: 58 | T16: Performing Arts | U16: 2 | V16: 40 | X16: 34 | Z16: 74 | AC16: Performing Arts | AD16: 2 | AE16: 40 | AG16: 34 | AI16: 74 | AL16: Dance | AM16: 2 | AN16: 40 | AP16: 34 | AR16: 74 | AU16: Games | AV16: 1 | AW16: 21 | AY16: 17 | BA16: 38 | BD16: Games | BE16: 1 | BF16: 21 | BH16: 17 | BJ16: 38 | BM16: Games | BN16: 1 | BO16: 21 | BQ16: 17 | BS16: 38
B17: Art Education | C17: 2 | D17: 44 | F17: 12 | H17: 56 | K17: Art Education | L17: 2 | M17: 40 | O17: 18 | Q17: 58 | T17: SST | U17: 4 | V17: 80 | X17: 68 | Z17: 148 | AC17: SST | AD17: 4 | AE17: 80 | AG17: 68 | AI17: 148 | AL17: SST | AM17: 4 | AN17: 80 | AP17: 68 | AR17: 148 | AU17: Music | AV17: 1 | AW17: 21 | AY17: 17 | BA17: 38 | BD17: Music | BE17: 1 | BF17: 21 | BH17: 17 | BJ17: 38 | BM17: Music | BN17: 1 | BO17: 21 | BQ17: 17 | BS17: 38
B18: Library | C18: 1 | D18: 22 | F18: 6 | H18: 28 | K18: Library | L18: 1 | M18: 20 | O18: 9 | Q18: 29 | T18: Games | U18: 1 | V18: 20 | X18: 17 | Z18: 37 | AC18: Games | AD18: 1 | AE18: 20 | AG18: 17 | AI18: 37 | AL18: Games | AM18: 1 | AN18: 20 | AP18: 17 | AR18: 37 | AU18: Painting | AV18: 2 | AW18: 42 | AY18: 34 | BA18: 76 | BD18: Painting | BE18: 2 | BF18: 42 | BH18: 34 | BJ18: 76 | BM18: Painting | BN18: 2 | BO18: 42 | BQ18: 34 | BS18: 76
B19: Computer Lab | C19: 1 | D19: 22 | F19: 6 | H19: 28 | K19: Computer Lab | L19: 1 | M19: 20 | O19: 9 | Q19: 29 | T19: Life skill | U19: 2 | V19: 40 | X19: 34 | Z19: 74 | AC19: Life skill | AD19: 2 | AE19: 40 | AG19: 34 | AI19: 74 | AL19: Painting | AM19: 2 | AN19: 40 | AP19: 34 | AR19: 74 | AU19: Craft | AV19: 2 | AW19: 42 | AY19: 34 | BA19: 76 | BD19: Craft | BE19: 2 | BF19: 42 | BH19: 34 | BJ19: 76 | BM19: Craft | BN19: 2 | BO19: 42 | BQ19: 34 | BS19: 76
H20: =SUM(H6:H19) -> 1120 | Q20: =SUM(Q6:Q19) -> 1160 | T20: RGA | U20: 1 | V20: 20 | X20: 17 | Z20: 37 | AC20: RGA | AD20: 1 | AE20: 20 | AG20: 17 | AI20: 37 | AL20: Life skill | AM20: 2 | AN20: 40 | AP20: 34 | AR20: 74 | AU20: Tabla | AV20: 2 | AW20: 42 | AY20: 34 | BA20: 76 | BD20: RGA | BE20: 1 | BF20: 21 | BH20: 17 | BJ20: 38 | BM20: RGA | BN20: 1 | BO20: 21 | BQ20: 17 | BS20: 38
T21: Computer Lab | U21: 1 | V21: 20 | X21: 17 | Z21: 37 | AC21: Computer Lab | AD21: 1 | AE21: 20 | AG21: 17 | AI21: 37 | AL21: RGA | AM21: 1 | AN21: 20 | AP21: 17 | AR21: 37 | AU21: RGA | AV21: 1 | AW21: 21 | AY21: 17 | BA21: 38 | BJ21: =SUM(BJ6:BJ20) -> 1140 | BS21: =SUM(BS6:BS20) -> 1140
BA22: =SUM(BA6:BA21) -> 1292
Z34: =SUM(Z6:Z21) -> 1406 | AI34: =SUM(AI6:AI21) -> 1406 | AR34: =SUM(AR6:AR21) -> 1369
